Workbook

Sheet Inputs
A1: Parameter | B1: Unit | C1: Value (base case) | D1: Low case | E1: High case | F1: Source
A2: Capex park high thb bn | B2: THB bn | C2: 200 | F2: Thai park proposal, news reports (12 and 15 May 2026)
A3: Capex park low thb bn | B3: THB bn | C3: 100 | F3: Thai park proposal, news report (27 March 2026)
A4: Claim additional visitors million per year | B4: million visits per year | C4: 10 | F4: Thai government proposal claims, news reports (2026)
A5: Claim revenue thb bn | B5: THB bn | C5: 150 | F5: Thai government proposal claims, news reports (2026)
A6: Claim share of gdp percent per year | B6: percent per year of GDP growth | C6: 1 | F6: Thai government proposal claims, news reports (2026)
A7: Discount rate eirr standard | B7: rate | C7: 0.09 | F7: ADB (2017) Guidelines for the Economic Analysis of Projects, paragraph 194 (printed page 53); DOI. http://dx.doi.org/10.22617/TIM178607-2
A8: Discount rate eirr social sector | B8: rate | C8: 0.06 | F8: ADB (2017) Guidelines for the Economic Analysis of Projects, paragraph 194 (printed page 53); DOI. http://dx.doi.org/10.22617/TIM178607-2
A9: Discount rate social nesdc | B9: rate | C9: 0.07 | F9: NESDC (2024) Guide to Public Investment Project Appraisal, section 6.2.2 (PDF page 28); range in section 6.2.1 (PDF page 26); URL. https://www.nesdc.go.th/wp-content/uploads/2025/05/article_20241009124821.pdf
A10: Discount rate social nesdc pre2025 | B10: rate | C10: 0.12 | F10: NESDC (2024) Guide to Public Investment Project Appraisal, section 6.2.2 (PDF page 28); URL. https://www.nesdc.go.th/wp-content/uploads/2025/05/article_20241009124821.pdf
A11: Conversion factor standard | B11: ratio | C11: 0.7 | F11: NESDC (2024) Guide to Public Investment Project Appraisal, summary of changes (PDF page 5); used when shadow prices cannot be computed; URL. https://www.nesdc.go.th/wp-content/uploads/2025/05/article_20241009124821.pdf
A12: Project life years | B12: years | C12: 20 | F12: NESDC Requirement
A13: Wacc financial | B13: rate | C13: 0.08 | F13: NESDC Requirement
... A47: Chonburi foreign arrivals 2019 | B47: persons | C47: 9966574 | F47: https://intelligencecenter.tat.or.th/articles/9907
A48: Utapao expansion progress overall percent | B48: percent complete | F48: https://www.eeco.or.th/en/u-tapao-airport-and-eastern-aviation-city/
A49: Utapao expansion opening year | B49: calendar year | C49: 2031 | F49: https://www.britishaviationgroup.co.uk/?p=24880
A50: High speed rail full service year eeco | B50: calendar year | C50: 2031 | F50: High-speed rail linking three airports, EEC Office. https://www.eeco.or.th/en/high-speed-rail-linking-three-airports/
A51: High speed rail full service year wikipedia | B51: calendar year | C51: 2029 | F51: Don Mueang-Suvarnabhumi-U-Tapao high-speed railway, Wikipedia. https://en.wikipedia.org/wiki/Don_Mueang%E2%80%93Suvarnabhumi%E2%80%93U-Tapao_high-speed_railway
A52: High speed rail status sep 2026 | B52: text | F52: Uttapao and High-Speed Rail: EEC's Make-or-Break Infrastructure Bet, Nation Thailand (7 Sep 2026). https://www.nationthailand.com/business/economy/40070765
A53: Motorway7 utapao extension length km | B53: kilometres | C53: 1.92 | F53: ADB news release, Thailand EEC infrastructure, 6 June 2025. https://www.adb.org/news/adb-supports-resilient-infrastructure-development-eastern-thailand
A54: Motorway7 utapao extension completion year | B54: calendar year | C54: 2028 | F54: https://www.thansettakij.com/economy/megaproject/630463
A55: Pattaya map ta phut motorway7 opening year | B55: calendar year (opened August 2020) | C55: 2020 | F55: Thai Prime Minister opens Pattaya-Map Ta Phut Highway, Pattaya Mail (24 Aug 2020). https://www.pattayamail.com/news/thai-prime-minister-opens-pattaya-map-ta-phut-highway-312223
A56: Tat spend per trip all nationalities 2023 | B56: THB per trip | C56: 50900 | F56: No external source located
A57: Tat spend per trip middle eastern 2023 | B57: THB per person per trip | C57: 88512 | F57: No external source located
A58: Tat spend per day uae 2023 | B58: THB per person per day | C58: 8834 | F58: No external source located
A59: Tat spend per night by nationality 2024 2025 | B59: THB per person per night | F59: No external source located
A60: Tat spend per trip by nationality 2024 2025 official | B60: THB per person per trip | F60: https://www.tatnews.org/?p=84576
A61: Mots spend per trip all tourists 2019 | B61: THB per international tourist per trip | C61: 48580 | F61: https://www.mots.go.th/download/article/article_20200123132729.pdf
A62: Mots spend per day all tourists 2019 | B62: THB per international tourist per day | C62: 5172.29 | F62: https://www.mots.go.th/download/article/article_20201104090605.pdf
A63: Intl avg length of stay 2016 days | B63: days | C63: 9.6 | F63: https://www.nso.go.th/public/e-book/Indicators-Economic/Indicators-Economic-2562/files/assets/basic-html/page134.html
A64: Intl avg length of stay 2024 days | B64: days | C64: 9.4 | F64: https://www.mots.go.th/images/v2022_c1331820-8936-4423-84cd-65278cebf658.xlsx
A65: Intl first visit share 2024 | B65: percent of international arrivals on first visit | F65: No external source located
A66: Thai domestic spend per trip 2024 | B66: THB per person per domestic trip | C66: 4000 | F66: No external source located
A67: Thai resident attraction visit share 2024 | B67: percent of attraction visits by Thai residents | F67: No external source located
A68: Intl arrivals 2025 | B68: persons | C68: 32974321 | F68: https://www.mots.go.th/images/v2022_5a7fbad7-1fcf-4410-a387-f29bb17486e2.xlsx
A69: Intl arrivals 2024 | B69: persons | C69: 35545714 | F69: https://www.mots.go.th/images/v2022_875a5789-3bcc-4700-bf55-b86fa7f1053c.xlsx
A70: Intl arrivals 2019 | B70: persons | C70: 39916251 | F70: https://www.mots.go.th/download/article/article_20201103140333.xlsx
A71: Intl arrivals 2020 | B71: persons | C71: 6725000 | F71: https://www.nso.go.th/public/e-book/Indicators-Economic/Thai_Economic_Indicators_2025/158
A72: Intl tourism receipts 2025 mots | B72: THB bn | C72: 1587.208 | F72: https://www.mots.go.th/images/v2022_5a7fbad7-1fcf-4410-a387-f29bb17486e2.xlsx
A73: Intl tourism receipts 2024 mots | B73: THB bn | C73: 1612.603 | F73: https://www.mots.go.th/images/v2022_c1331820-8936-4423-84cd-65278cebf658.xlsx
...

Sheet Appraisal
A1: Park-only operator financial appraisal (THB billion unless stated)
A4: Parameter | B4: Park-only
A5: Cash operating cost, share of revenue | B5: =Inputs!$C$132/Inputs!$C$83 -> 0.77122153
A6: WACC | B6: =Inputs!$C$142 -> 0.08
A7: Operating life (years) | B7: =Inputs!$C$140 -> 20
A8: Construction years | B8: =Inputs!$C$141 -> 2
A9: Capital cost (THB bn) | B9: =Inputs!$C$163 -> 200
A10: Attendance (million visits a year) | B10: =Inputs!$C$143 -> 7.5
A11: International share of attendance | B11: =Inputs!$C$144 -> 0.59
A12: Physical visit cap (million visits a year) | B12: =MIN(Inputs!$C$25/Inputs!$C$154,Inputs!$C$158*365*Inputs!$C$153/Inputs!$C$152)/1000000 -> 1.85
A13: Ticket revenue per visit (THB) | B13: =Inputs!$C$151 -> 2877
A14: Operator visits per operating year (million) | B14: =B10-MAX(B10*B11-B12,0) -> 4.925
A15: Operator revenue per operating year (THB bn) | B15: =B14*(B13+B19*Inputs!$D$147)/1000 -> 23.339575
A16: Replacement capex, share of capital per operating year | B16: =Inputs!$C$164 -> 0
A17: Corporate income tax rate | B17: =Inputs!$C$166 -> 0.2
A18: Tax depreciation years | B18: =Inputs!$C$167 -> 20
A19: On-site income included (1 = yes) | B19: 1
A20: Results | B20: Park-only
A21: Operator NPV before tax at WACC (THB bn) | B21: =SUM(K41:K85) -> -144.05102
A22: Operator NPV after tax (THB bn) | B22: =IF($B$18<$B$7,"n/a",SUM(R41:R85)) -> -144.05102
A23: Operator IRR after tax | B23: =IF($B$18<$B$7,"n/a",IRR(Q41:Q85,-0.1)) -> -0.05150944
A24: Break-even capital cost (THB bn) | B24: =B15*(1-B5)*B27/(B16*B27+B28/B9) -> 50.408561
A25: Break-even attendance (million visits a year) | B25: =B10-B21/((1-B5)*(B13+B19*Inputs!$D$147)/1000*(1-B11)*B27) -> 43.14715
A27: Annuity factor over operating years | B27: =SUMPRODUCT(B41:B85,D41:D85) -> 9.0908772
A28: Present value of capital cost (THB bn) | B28: =SUMPRODUCT(E41:E85,B41:B85) -> 192.59259
A31: Ledger covers the operating life | B31: =IF($B$8+$B$7-1<=MAX($A$41:$A$85),"Yes","No") -> Yes
A32: Tax depreciation covers the operating life | B32: =IF(B18<B7,"No","Yes") -> Yes
A33: Cumulative cash flow over the operating life, before tax (THB bn) | B33: =SUM(J41:J85) -> -93.208156
A34: Years of operation needed for nominal payback | B34: =IF(B15*(1-B5)-B16*B9<=0,"never",B9/(B15*(1-B5)-B16*B9)) -> 37.456044
A35: Estimated nominal payback year (from start of construction) | B35: =IF(ISNUMBER(B34),B8+B34,"never") -> 39.456044
A36: Nominal payback within the operating life | B36: =IF(ISNUMBER(B34),IF(B34<=B7,"Yes","No"),"No") -> No
A37: Estimated discounted payback year at WACC (from start of construction) | B37: =IF(B15*(1-B5)-B16*B9<=0,"never",IF(B28*B6*(1+B6)^(B8-1)/(B15*(1-B5)-B16*B9)>=1,"never",B8-LN(1-B28*B6*(1+B6)^(B8-1)/(B15*(1-B5)-B16*B9))/LN(1+B6))) -> never
A39: Annual ledger, park-only
A40: Year | B40: Discount factor | C40: Construction | D40: Operating | E40: Capital cost | F40: Operator visits (million) | G40: Revenue | H40: Cash operating cost | I40: Replacement capex | J40: Cash flow before tax | K40: Present value before tax | L40: Tax depreciation | M40: Taxable income | N40: Cumulative taxable income | O40: Cumulative tax due | P40: Tax paid | Q40: Cash flow after tax | R40: Present value after tax | S40: Cumulative cash flow after tax | U40: Capital outflow, absolute (THB bn) | V40: Operating cash flow (THB bn)
A41: 0 | B41: =1/(1+$B$6)^A41 -> 1 | C41: =IF(A41<$B$8,1,0) -> 1 | D41: =IF(AND(A41>=$B$8,A41<$B$8+$B$7),1,0) -> 0 | E41: =C41*$B$9/$B$8 -> 100 | F41: =D41*$B$14 -> 0 | G41: =F41*($B$13+$B$19*Inputs!$D$147)/1000 -> 0 | H41: =$B$5*G41 -> 0 | I41: =D41*$B$16*$B$9 -> 0 | J41: =G41-H41-E41-I41 -> -100 | K41: =J41*B41 -> -100 | L41: =IF(AND(A41>=$B$8,A41<$B$8+$B$18),$B$9/$B$18,0) -> 0 | M41: =G41-H41-L41 -> 0 | N41: =SUM($M$41:M41) -> 0 | O41: =$B$17*MAX(0,N41) -> 0 | P41: =MAX(0,O41) -> 0 | Q41: =J41-P41 -> -100 | R41: =Q41*B41 -> -100 | S41: =SUM($Q$41:Q41) -> -100 | U41: =IF(J41<0,-J41,NA()) -> 100 | V41: =IF(J41>0,J41,NA()) -> #N/A
A42: 1 | B42: =1/(1+$B$6)^A42 -> 0.92592593 | C42: =IF(A42<$B$8,1,0) -> 1 | D42: =IF(AND(A42>=$B$8,A42<$B$8+$B$7),1,0) -> 0 | E42: =C42*$B$9/$B$8 -> 100 | F42: =D42*$B$14 -> 0 | G42: =F42*($B$13+$B$19*Inputs!$D$147)/1000 -> 0 | H42: =$B$5*G42 -> 0 | I42: =D42*$B$16*$B$9 -> 0 | J42: =G42-H42-E42-I42 -> -100 | K42: =J42*B42 -> -92.592593 | L42: =IF(AND(A42>=$B$8,A42<$B$8+$B$18),$B$9/$B$18,0) -> 0 | M42: =G42-H42-L42 -> 0 | N42: =SUM($M$41:M42) -> 0 | O42: =$B$17*MAX(0,N42) -> 0 | P42: =MAX(0,O42-O41) -> 0 | Q42: =J42-P42 -> -100 | R42: =Q42*B42 -> -92.592593 | S42: =SUM($Q$41:Q42) -> -200 | U42: =IF(J42<0,-J42,NA()) -> 100 | V42: =IF(J42>0,J42,NA()) -> #N/A
A43: 2 | B43: =1/(1+$B$6)^A43 -> 0.85733882 | C43: =IF(A43<$B$8,1,0) -> 0 | D43: =IF(AND(A43>=$B$8,A43<$B$8+$B$7),1,0) -> 1 | E43: =C43*$B$9/$B$8 -> 0 | F43: =D43*$B$14 -> 4.925 | G43: =F43*($B$13+$B$19*Inputs!$D$147)/1000 -> 23.339575 | H43: =$B$5*G43 -> 17.999983 | I43: =D43*$B$16*$B$9 -> 0 | J43: =G43-H43-E43-I43 -> 5.3395922 | K43: =J43*B43 -> 4.5778397 | L43: =IF(AND(A43>=$B$8,A43<$B$8+$B$18),$B$9/$B$18,0) -> 10 | M43: =G43-H43-L43 -> -4.6604078 | N43: =SUM($M$41:M43) -> -4.6604078 | O43: =$B$17*MAX(0,N43) -> 0 | P43: =MAX(0,O43-O42) -> 0 | Q43: =J43-P43 -> 5.3395922 | R43: =Q43*B43 -> 4.5778397 | S43: =SUM($Q$41:Q43) -> -194.66041 | U43: =IF(J43<0,-J43,NA()) -> #N/A | V43: =IF(J43>0,J43,NA()) -> 5.3395922
A44: 3 | B44: =1/(1+$B$6)^A44 -> 0.79383224 | C44: =IF(A44<$B$8,1,0) -> 0 | D44: =IF(AND(A44>=$B$8,A44<$B$8+$B$7),1,0) -> 1 | E44: =C44*$B$9/$B$8 -> 0 | F44: =D44*$B$14 -> 4.925 | G44: =F44*($B$13+$B$19*Inputs!$D$147)/1000 -> 23.339575 | H44: =$B$5*G44 -> 17.999983 | I44: =D44*$B$16*$B$9 -> 0 | J44: =G44-H44-E44-I44 -> 5.3395922 | K44: =J44*B44 -> 4.2387405 | L44: =IF(AND(A44>=$B$8,A44<$B$8+$B$18),$B$9/$B$18,0) -> 10 | M44: =G44-H44-L44 -> -4.6604078 | N44: =SUM($M$41:M44) -> -9.3208156 | O44: =$B$17*MAX(0,N44) -> 0 | P44: =MAX(0,O44-O43) -> 0 | Q44: =J44-P44 -> 5.3395922 | R44: =Q44*B44 -> 4.2387405 | S44: =SUM($Q$41:Q44) -> -189.32082 | U44: =IF(J44<0,-J44,NA()) -> #N/A | V44: =IF(J44>0,J44,NA()) -> 5.3395922
A45: 4 | B45: =1/(1+$B$6)^A45 -> 0.73502985 | C45: =IF(A45<$B$8,1,0) -> 0 | D45: =IF(AND(A45>=$B$8,A45<$B$8+$B$7),1,0) -> 1 | E45: =C45*$B$9/$B$8 -> 0 | F45: =D45*$B$14 -> 4.925 | G45: =F45*($B$13+$B$19*Inputs!$D$147)/1000 -> 23.339575 | H45: =$B$5*G45 -> 17.999983 | I45: =D45*$B$16*$B$9 -> 0 | J45: =G45-H45-E45-I45 -> 5.3395922 | K45: =J45*B45 -> 3.9247597 | L45: =IF(AND(A45>=$B$8,A45<$B$8+$B$18),$B$9/$B$18,0) -> 10 | M45: =G45-H45-L45 -> -4.6604078 | N45: =SUM($M$41:M45) -> -13.981223 | O45: =$B$17*MAX(0,N45) -> 0 | P45: =MAX(0,O45-O44) -> 0 | Q45: =J45-P45 -> 5.3395922 | R45: =Q45*B45 -> 3.9247597 | S45: =SUM($Q$41:Q45) -> -183.98122 | U45: =IF(J45<0,-J45,NA()) -> #N/A | V45: =IF(J45>0,J45,NA()) -> 5.3395922
A46: 5 | B46: =1/(1+$B$6)^A46 -> 0.6805832 | C46: =IF(A46<$B$8,1,0) -> 0 | D46: =IF(AND(A46>=$B$8,A46<$B$8+$B$7),1,0) -> 1 | E46: =C46*$B$9/$B$8 -> 0 | F46: =D46*$B$14 -> 4.925 | G46: =F46*($B$13+$B$19*Inputs!$D$147)/1000 -> 23.339575 | H46: =$B$5*G46 -> 17.999983 | I46: =D46*$B$16*$B$9 -> 0 | J46: =G46-H46-E46-I46 -> 5.3395922 | K46: =J46*B46 -> 3.6340367 | L46: =IF(AND(A46>=$B$8,A46<$B$8+$B$18),$B$9/$B$18,0) -> 10 | M46: =G46-H46-L46 -> -4.6604078 | N46: =SUM($M$41:M46) -> -18.641631 | O46: =$B$17*MAX(0,N46) -> 0 | P46: =MAX(0,O46-O45) -> 0 | Q46: =J46-P46 -> 5.3395922 | R46: =Q46*B46 -> 3.6340367 | S46: =SUM($Q$41:Q46) -> -178.64163 | U46: =IF(J46<0,-J46,NA()) -> #N/A | V46: =IF(J46>0,J46,NA()) -> 5.3395922
...

Sheet Charts
A1: Estimated discounted payback year at WACC (from start of construction)
