Workbook

Sheet Inputs
A1: Parameter | B1: Unit | C1: Value (base case) | D1: Low case | E1: High case | F1: Source
A2: Capex complex thb bn | B2: THB bn | C2: 300 | F2: Thai complex proposal, news reports (12 February 2026)
A3: Capex park high thb bn | B3: THB bn | C3: 200 | F3: Thai park proposal, news reports (12 and 15 May 2026)
A4: Capex park low thb bn | B4: THB bn | C4: 100 | F4: Thai park proposal, news report (27 March 2026)
A5: Claim additional visitors million per year | B5: million visits per year | C5: 10 | F5: Thai government proposal claims, news reports (2026)
A6: Claim revenue thb bn | B6: THB bn | C6: 150 | F6: Thai government proposal claims, news reports (2026)
A7: Claim share of gdp percent per year | B7: percent per year of GDP growth | C7: 1 | F7: Thai government proposal claims, news reports (2026)
A8: Discount rate eirr standard | B8: rate | C8: 0.09 | F8: ADB (2017) Guidelines for the Economic Analysis of Projects, paragraph 194 (printed page 53); DOI. http://dx.doi.org/10.22617/TIM178607-2
A9: Discount rate eirr social sector | B9: rate | C9: 0.06 | F9: ADB (2017) Guidelines for the Economic Analysis of Projects, paragraph 194 (printed page 53); DOI. http://dx.doi.org/10.22617/TIM178607-2
A10: Discount rate social nesdc | B10: rate | C10: 0.07 | F10: NESDC (2024) Guide to Public Investment Project Appraisal, section 6.2.2 (PDF page 28); range in section 6.2.1 (PDF page 26); URL. https://www.nesdc.go.th/wp-content/uploads/2025/05/article_20241009124821.pdf
A11: Discount rate social nesdc pre2025 | B11: rate | C11: 0.12 | F11: NESDC (2024) Guide to Public Investment Project Appraisal, section 6.2.2 (PDF page 28); URL. https://www.nesdc.go.th/wp-content/uploads/2025/05/article_20241009124821.pdf
A12: Conversion factor standard | B12: ratio | C12: 0.7 | F12: NESDC (2024) Guide to Public Investment Project Appraisal, summary of changes (PDF page 5); used when shadow prices cannot be computed; URL. https://www.nesdc.go.th/wp-content/uploads/2025/05/article_20241009124821.pdf
A13: Project life years | B13: years | C13: 20 | F13: NESDC Requirement
... A48: Chonburi foreign arrivals 2019 | B48: persons | C48: 9966574 | F48: https://intelligencecenter.tat.or.th/articles/9907
A49: Utapao expansion progress overall percent | B49: percent complete | F49: https://www.eeco.or.th/en/u-tapao-airport-and-eastern-aviation-city/
A50: Utapao expansion opening year | B50: calendar year | C50: 2031 | F50: https://www.britishaviationgroup.co.uk/?p=24880
A51: High speed rail full service year eeco | B51: calendar year | C51: 2031 | F51: High-speed rail linking three airports, EEC Office. https://www.eeco.or.th/en/high-speed-rail-linking-three-airports/
A52: High speed rail full service year wikipedia | B52: calendar year | C52: 2029 | F52: Don Mueang-Suvarnabhumi-U-Tapao high-speed railway, Wikipedia. https://en.wikipedia.org/wiki/Don_Mueang%E2%80%93Suvarnabhumi%E2%80%93U-Tapao_high-speed_railway
A53: High speed rail status sep 2026 | B53: text | F53: Uttapao and High-Speed Rail: EEC's Make-or-Break Infrastructure Bet, Nation Thailand (7 Sep 2026). https://www.nationthailand.com/business/economy/40070765
A54: Motorway7 utapao extension length km | B54: kilometres | C54: 1.92 | F54: ADB news release, Thailand EEC infrastructure, 6 June 2025. https://www.adb.org/news/adb-supports-resilient-infrastructure-development-eastern-thailand
A55: Motorway7 utapao extension completion year | B55: calendar year | C55: 2028 | F55: https://www.thansettakij.com/economy/megaproject/630463
A56: Pattaya map ta phut motorway7 opening year | B56: calendar year (opened August 2020) | C56: 2020 | F56: Thai Prime Minister opens Pattaya-Map Ta Phut Highway, Pattaya Mail (24 Aug 2020). https://www.pattayamail.com/news/thai-prime-minister-opens-pattaya-map-ta-phut-highway-312223
A57: Tat spend per trip all nationalities 2023 | B57: THB per trip | C57: 50900 | F57: No external source located
A58: Tat spend per trip middle eastern 2023 | B58: THB per person per trip | C58: 88512 | F58: No external source located
A59: Tat spend per day uae 2023 | B59: THB per person per day | C59: 8834 | F59: No external source located
A60: Tat spend per night by nationality 2024 2025 | B60: THB per person per night | F60: No external source located
A61: Tat spend per trip by nationality 2024 2025 official | B61: THB per person per trip | F61: https://www.tatnews.org/?p=84576
A62: Mots spend per trip all tourists 2019 | B62: THB per international tourist per trip | C62: 48580 | F62: https://www.mots.go.th/download/article/article_20200123132729.pdf
A63: Mots spend per day all tourists 2019 | B63: THB per international tourist per day | C63: 5172.29 | F63: https://www.mots.go.th/download/article/article_20201104090605.pdf
A64: Intl avg length of stay 2016 days | B64: days | C64: 9.6 | F64: https://www.nso.go.th/public/e-book/Indicators-Economic/Indicators-Economic-2562/files/assets/basic-html/page134.html
A65: Intl avg length of stay 2024 days | B65: days | C65: 9.4 | F65: https://www.mots.go.th/images/v2022_c1331820-8936-4423-84cd-65278cebf658.xlsx
A66: Intl first visit share 2024 | B66: percent of international arrivals on first visit | F66: No external source located
A67: Thai domestic spend per trip 2024 | B67: THB per person per domestic trip | C67: 4000 | F67: No external source located
A68: Thai resident attraction visit share 2024 | B68: percent of attraction visits by Thai residents | F68: No external source located
A69: Intl arrivals 2025 | B69: persons | C69: 32974321 | F69: https://www.mots.go.th/images/v2022_5a7fbad7-1fcf-4410-a387-f29bb17486e2.xlsx
A70: Intl arrivals 2024 | B70: persons | C70: 35545714 | F70: https://www.mots.go.th/images/v2022_875a5789-3bcc-4700-bf55-b86fa7f1053c.xlsx
A71: Intl arrivals 2019 | B71: persons | C71: 39916251 | F71: https://www.mots.go.th/download/article/article_20201103140333.xlsx
A72: Intl arrivals 2020 | B72: persons | C72: 6725000 | F72: https://www.nso.go.th/public/e-book/Indicators-Economic/Thai_Economic_Indicators_2025/158
A73: Intl tourism receipts 2025 mots | B73: THB bn | C73: 1587.208 | F73: https://www.mots.go.th/images/v2022_5a7fbad7-1fcf-4410-a387-f29bb17486e2.xlsx
A74: Intl tourism receipts 2024 mots | B74: THB bn | C74: 1612.603 | F74: https://www.mots.go.th/images/v2022_c1331820-8936-4423-84cd-65278cebf658.xlsx
...

Sheet Appraisal
A1: Park-only operator financial appraisal (THB billion unless stated)
A4: Parameter | B4: Park-only | C4: Complex, 300 bn
A5: Cash operating cost, share of revenue | B5: =Inputs!$C$133/Inputs!$C$84 -> 0.77122153 | C5: =B5 -> 0.77122153
A6: WACC | B6: =Inputs!$C$143 -> 0.08 | C6: =B6 -> 0.08
A7: Operating life (years) | B7: =Inputs!$C$141 -> 20 | C7: =B7 -> 20
A8: Construction years | B8: =Inputs!$C$142 -> 2 | C8: =B8 -> 2
A9: Capital cost (THB bn) | B9: =Inputs!$C$164 -> 200 | C9: =Inputs!$C$2 -> 300
A10: Attendance (million visits a year) | B10: =Inputs!$C$144 -> 7.5 | C10: =B10 -> 7.5
A11: International share of attendance | B11: =Inputs!$C$145 -> 0.59 | C11: =B11 -> 0.59
A12: Physical visit cap (million visits a year) | B12: =MIN(Inputs!$C$26/Inputs!$C$155,Inputs!$C$159*365*Inputs!$C$154/Inputs!$C$153)/1000000 -> 1.85 | C12: =B12 -> 1.85
A13: Ticket revenue per visit (THB) | B13: =Inputs!$C$152 -> 2877 | C13: =B13 -> 2877
A14: Operator visits per operating year (million) | B14: =B10-MAX(B10*B11-B12,0) -> 4.925 | C14: =B14 -> 4.925
A15: Operator revenue per operating year (THB bn) | B15: =B14*(B13+B19*Inputs!$D$148)/1000 -> 23.339575 | C15: =B14*(C13+C19*Inputs!$D$148)/1000 -> 14.169225
A16: Replacement capex, share of capital per operating year | B16: =Inputs!$C$165 -> 0 | C16: =B16 -> 0
A17: Corporate income tax rate | B17: =Inputs!$C$167 -> 0.2 | C17: =B17 -> 0.2
A18: Tax depreciation years | B18: =Inputs!$C$168 -> 20 | C18: =B18 -> 20
A19: On-site income included (1 = yes) | B19: 1 | C19: 0
A20: Results | B20: Park-only | C20: Complex, 300 bn
A21: Operator NPV before tax at WACC (THB bn) | B21: =SUM(K41:K63) -> -144.05102 | C21: =(C15*(1-C5)-C16*C9)*B27-(C9/B9)*B28 -> -259.41978
A22: Operator NPV after tax (THB bn) | B22: =IF($B$18<$B$7,"n/a",SUM(R41:R63)) -> -144.05102 | C22: =IF(C18<C7,"n/a",C21) -> -259.41978
A23: Operator IRR after tax | B23: =IF($B$18<$B$7,"n/a",IRR(Q41:Q63,-0.1)) -> -0.05150944 | C23: n/a
A24: Break-even capital cost (THB bn) | B24: =B15*(1-B5)*B27/(B16*B27+B28/B9) -> 50.408561 | C24: =B24 -> 50.408561
A25: Break-even attendance (million visits a year) | B25: =B10-B21/((1-B5)*(B13+B19*Inputs!$D$148)/1000*(1-B11)*B27) -> 43.14715 | C25: =B10-C21/((1-C5)*C13/1000*(1-C11)*B27) -> 113.24465
A27: Annuity factor over operating years | B27: =SUMPRODUCT(B41:B63,D41:D63) -> 9.0908772
A28: Present value of capital cost (THB bn) | B28: =SUMPRODUCT(E41:E63,B41:B63) -> 192.59259
A32: Tax depreciation covers the operating life | B32: =IF(B18<B7,"No","Yes") -> Yes | C32: =IF(C18<C7,"No","Yes") -> Yes
A33: Cumulative cash flow over the operating life, before tax (THB bn) | B33: =SUM(J41:J63) -> -93.208156 | C33: =(C15*(1-C5)-C16*C9)*B7-C9 -> -235.16773
A34: Years of operation needed for nominal payback | B34: =IF(B15*(1-B5)-B16*B9<=0,"never",B9/(B15*(1-B5)-B16*B9)) -> 37.456044 | C34: =IF(C15*(1-C5)-C16*C9<=0,"never",C9/(C15*(1-C5)-C16*C9)) -> 92.546503
A35: Estimated nominal payback year (from start of construction) | B35: =IF(ISNUMBER(B34),B8+B34,"never") -> 39.456044 | C35: =IF(ISNUMBER(C34),C8+C34,"never") -> 94.546503
A36: Nominal payback within the operating life | B36: =IF(ISNUMBER(B34),IF(B34<=B7,"Yes","No"),"No") -> No | C36: =IF(ISNUMBER(C34),IF(C34<=C7,"Yes","No"),"No") -> No
A37: Estimated discounted payback year at WACC (from start of construction) | B37: =IF(B15*(1-B5)-B16*B9<=0,"never",IF(B28*B6*(1+B6)^(B8-1)/(B15*(1-B5)-B16*B9)>=1,"never",B8-LN(1-B28*B6*(1+B6)^(B8-1)/(B15*(1-B5)-B16*B9))/LN(1+B6))) -> never | C37: =IF(C15*(1-C5)-C16*C9<=0,"never",IF((C9/B9)*B28*C6*(1+C6)^(C8-1)/(C15*(1-C5)-C16*C9)>=1,"never",C8-LN(1-(C9/B9)*B28*C6*(1+C6)^(C8-1)/(C15*(1-C5)-C16*C9))/LN(1+C6))) -> never
A39: Annual ledger, park-only
A40: Year | B40: Discount factor | C40: Construction | D40: Operating | E40: Capital cost | F40: Operator visits (million) | G40: Revenue | H40: Cash operating cost | I40: Replacement capex | J40: Cash flow before tax | K40: Present value before tax | L40: Tax depreciation | M40: Taxable income | N40: Cumulative taxable income | O40: Cumulative tax due | P40: Tax paid | Q40: Cash flow after tax | R40: Present value after tax | S40: Cumulative cash flow after tax | U40: Capital outflow, absolute (THB bn) | V40: Operating cash flow (THB bn)
A41: 0 | B41: =1/(1+$B$6)^A41 -> 1 | C41: =IF(A41<$B$8,1,0) -> 1 | D41: =IF(AND(A41>=$B$8,A41<$B$8+$B$7),1,0) -> 0 | E41: =C41*$B$9/$B$8 -> 100 | F41: =D41*$B$14 -> 0 | G41: =F41*($B$13+$B$19*Inputs!$D$148)/1000 -> 0 | H41: =$B$5*G41 -> 0 | I41: =D41*$B$16*$B$9 -> 0 | J41: =G41-H41-E41-I41 -> -100 | K41: =J41*B41 -> -100 | L41: =IF(AND(A41>=$B$8,A41<$B$8+$B$18),$B$9/$B$18,0) -> 0 | M41: =G41-H41-L41 -> 0 | N41: =SUM($M$41:M41) -> 0 | O41: =$B$17*MAX(0,N41) -> 0 | P41: =MAX(0,O41) -> 0 | Q41: =J41-P41 -> -100 | R41: =Q41*B41 -> -100 | S41: =SUM($Q$41:Q41) -> -100 | U41: =IF(J41<0,-J41,NA()) -> 100 | V41: =IF(J41>0,J41,NA()) -> #N/A
A42: 1 | B42: =1/(1+$B$6)^A42 -> 0.92592593 | C42: =IF(A42<$B$8,1,0) -> 1 | D42: =IF(AND(A42>=$B$8,A42<$B$8+$B$7),1,0) -> 0 | E42: =C42*$B$9/$B$8 -> 100 | F42: =D42*$B$14 -> 0 | G42: =F42*($B$13+$B$19*Inputs!$D$148)/1000 -> 0 | H42: =$B$5*G42 -> 0 | I42: =D42*$B$16*$B$9 -> 0 | J42: =G42-H42-E42-I42 -> -100 | K42: =J42*B42 -> -92.592593 | L42: =IF(AND(A42>=$B$8,A42<$B$8+$B$18),$B$9/$B$18,0) -> 0 | M42: =G42-H42-L42 -> 0 | N42: =SUM($M$41:M42) -> 0 | O42: =$B$17*MAX(0,N42) -> 0 | P42: =MAX(0,O42-O41) -> 0 | Q42: =J42-P42 -> -100 | R42: =Q42*B42 -> -92.592593 | S42: =SUM($Q$41:Q42) -> -200 | U42: =IF(J42<0,-J42,NA()) -> 100 | V42: =IF(J42>0,J42,NA()) -> #N/A
A43: 2 | B43: =1/(1+$B$6)^A43 -> 0.85733882 | C43: =IF(A43<$B$8,1,0) -> 0 | D43: =IF(AND(A43>=$B$8,A43<$B$8+$B$7),1,0) -> 1 | E43: =C43*$B$9/$B$8 -> 0 | F43: =D43*$B$14 -> 4.925 | G43: =F43*($B$13+$B$19*Inputs!$D$148)/1000 -> 23.339575 | H43: =$B$5*G43 -> 17.999983 | I43: =D43*$B$16*$B$9 -> 0 | J43: =G43-H43-E43-I43 -> 5.3395922 | K43: =J43*B43 -> 4.5778397 | L43: =IF(AND(A43>=$B$8,A43<$B$8+$B$18),$B$9/$B$18,0) -> 10 | M43: =G43-H43-L43 -> -4.6604078 | N43: =SUM($M$41:M43) -> -4.6604078 | O43: =$B$17*MAX(0,N43) -> 0 | P43: =MAX(0,O43-O42) -> 0 | Q43: =J43-P43 -> 5.3395922 | R43: =Q43*B43 -> 4.5778397 | S43: =SUM($Q$41:Q43) -> -194.66041 | U43: =IF(J43<0,-J43,NA()) -> #N/A | V43: =IF(J43>0,J43,NA()) -> 5.3395922
A44: 3 | B44: =1/(1+$B$6)^A44 -> 0.79383224 | C44: =IF(A44<$B$8,1,0) -> 0 | D44: =IF(AND(A44>=$B$8,A44<$B$8+$B$7),1,0) -> 1 | E44: =C44*$B$9/$B$8 -> 0 | F44: =D44*$B$14 -> 4.925 | G44: =F44*($B$13+$B$19*Inputs!$D$148)/1000 -> 23.339575 | H44: =$B$5*G44 -> 17.999983 | I44: =D44*$B$16*$B$9 -> 0 | J44: =G44-H44-E44-I44 -> 5.3395922 | K44: =J44*B44 -> 4.2387405 | L44: =IF(AND(A44>=$B$8,A44<$B$8+$B$18),$B$9/$B$18,0) -> 10 | M44: =G44-H44-L44 -> -4.6604078 | N44: =SUM($M$41:M44) -> -9.3208156 | O44: =$B$17*MAX(0,N44) -> 0 | P44: =MAX(0,O44-O43) -> 0 | Q44: =J44-P44 -> 5.3395922 | R44: =Q44*B44 -> 4.2387405 | S44: =SUM($Q$41:Q44) -> -189.32082 | U44: =IF(J44<0,-J44,NA()) -> #N/A | V44: =IF(J44>0,J44,NA()) -> 5.3395922
A45: 4 | B45: =1/(1+$B$6)^A45 -> 0.73502985 | C45: =IF(A45<$B$8,1,0) -> 0 | D45: =IF(AND(A45>=$B$8,A45<$B$8+$B$7),1,0) -> 1 | E45: =C45*$B$9/$B$8 -> 0 | F45: =D45*$B$14 -> 4.925 | G45: =F45*($B$13+$B$19*Inputs!$D$148)/1000 -> 23.339575 | H45: =$B$5*G45 -> 17.999983 | I45: =D45*$B$16*$B$9 -> 0 | J45: =G45-H45-E45-I45 -> 5.3395922 | K45: =J45*B45 -> 3.9247597 | L45: =IF(AND(A45>=$B$8,A45<$B$8+$B$18),$B$9/$B$18,0) -> 10 | M45: =G45-H45-L45 -> -4.6604078 | N45: =SUM($M$41:M45) -> -13.981223 | O45: =$B$17*MAX(0,N45) -> 0 | P45: =MAX(0,O45-O44) -> 0 | Q45: =J45-P45 -> 5.3395922 | R45: =Q45*B45 -> 3.9247597 | S45: =SUM($Q$41:Q45) -> -183.98122 | U45: =IF(J45<0,-J45,NA()) -> #N/A | V45: =IF(J45>0,J45,NA()) -> 5.3395922
A46: 5 | B46: =1/(1+$B$6)^A46 -> 0.6805832 | C46: =IF(A46<$B$8,1,0) -> 0 | D46: =IF(AND(A46>=$B$8,A46<$B$8+$B$7),1,0) -> 1 | E46: =C46*$B$9/$B$8 -> 0 | F46: =D46*$B$14 -> 4.925 | G46: =F46*($B$13+$B$19*Inputs!$D$148)/1000 -> 23.339575 | H46: =$B$5*G46 -> 17.999983 | I46: =D46*$B$16*$B$9 -> 0 | J46: =G46-H46-E46-I46 -> 5.3395922 | K46: =J46*B46 -> 3.6340367 | L46: =IF(AND(A46>=$B$8,A46<$B$8+$B$18),$B$9/$B$18,0) -> 10 | M46: =G46-H46-L46 -> -4.6604078 | N46: =SUM($M$41:M46) -> -18.641631 | O46: =$B$17*MAX(0,N46) -> 0 | P46: =MAX(0,O46-O45) -> 0 | Q46: =J46-P46 -> 5.3395922 | R46: =Q46*B46 -> 3.6340367 | S46: =SUM($Q$41:Q46) -> -178.64163 | U46: =IF(J46<0,-J46,NA()) -> #N/A | V46: =IF(J46>0,J46,NA()) -> 5.3395922
A47: 6 | B47: =1/(1+$B$6)^A47 -> 0.63016963 | C47: =IF(A47<$B$8,1,0) -> 0 | D47: =IF(AND(A47>=$B$8,A47<$B$8+$B$7),1,0) -> 1 | E47: =C47*$B$9/$B$8 -> 0 | F47: =D47*$B$14 -> 4.925 | G47: =F47*($B$13+$B$19*Inputs!$D$148)/1000 -> 23.339575 | H47: =$B$5*G47 -> 17.999983 | I47: =D47*$B$16*$B$9 -> 0 | J47: =G47-H47-E47-I47 -> 5.3395922 | K47: =J47*B47 -> 3.3648488 | L47: =IF(AND(A47>=$B$8,A47<$B$8+$B$18),$B$9/$B$18,0) -> 10 | M47: =G47-H47-L47 -> -4.6604078 | N47: =SUM($M$41:M47) -> -23.302039 | O47: =$B$17*MAX(0,N47) -> 0 | P47: =MAX(0,O47-O46) -> 0 | Q47: =J47-P47 -> 5.3395922 | R47: =Q47*B47 -> 3.3648488 | S47: =SUM($Q$41:Q47) -> -173.30204 | U47: =IF(J47<0,-J47,NA()) -> #N/A | V47: =IF(J47>0,J47,NA()) -> 5.3395922
...

Sheet Charts
A1: Park-only operator appraisal: charts
