Workbook

Sheet Inputs
A1: Input assumptions: every row of inputs.csv and assumptions.csv (base case values)
A2: Values are copied from disney-tourism-thailand/data/appraisal. Column C is the base case used by the appraisal. Status and source are copied from the source file.
A3: File | B3: Parameter | C3: Value (base case) | D3: Low case | E3: High case | F3: Unit | G3: Status | H3: Source or basis
A4: inputs.csv | B4: capex_complex_thb_bn | C4: 300 | F4: THB bn | G4: from proposal (not verified; reported in news on 12 February 2026 and repeated later; no official statement read) | H4: data/processed/thailand_proposal.json scenario complex_total
A5: inputs.csv | B5: capex_park_high_thb_bn | C5: 200 | F5: THB bn | G5: from proposal (not verified; reported in news on 12 and 15 May 2026; no official statement read) | H5: data/processed/thailand_proposal.json scenario park_high
A6: inputs.csv | B6: capex_park_low_thb_bn | C6: 100 | F6: THB bn | G6: from proposal (not verified; lower bound of a range reported on 27 March 2026; no official statement read) | H6: data/processed/thailand_proposal.json scenario park_low
A7: inputs.csv | B7: claim_additional_visitors_million_per_year | C7: 10 | F7: million visits per year | G7: claim (reference only; reported in news on 3 February 2026 as a conditional annual figure with no base year) | H7: data/processed/thailand_proposal.json ministerial_claims
A8: inputs.csv | B8: claim_revenue_thb_bn | C8: 150 | F8: THB bn | G8: claim (reference only; reported in news on 3 February 2026 as more than THB 150 billion, conditional, with no period) | H8: data/processed/thailand_proposal.json ministerial_claims
A9: inputs.csv | B9: claim_share_of_gdp_percent_per_year | C9: 1 | F9: percent per year of GDP growth | G9: claim (reference only; reported on 3 February 2026 as an effect of 1 percent a year on the GDP growth rate, not a share of GDP) | H9: data/processed/thailand_proposal.json ministerial_claims
A10: inputs.csv | B10: discount_rate_eirr_standard | C10: 0.09 | F10: rate | G10: sourced (ADB 2017; cross-check only) | H10: ADB (2017) Guidelines for the Economic Analysis of Projects, paragraph 194 (printed page 53); DOI http://dx.doi.org/10.22617/TIM178607-2; URL https://www.adb.org/sites/default/files/institutional-document/32256/economic-analysis-projects.pdf
A11: inputs.csv | B11: discount_rate_eirr_social_sector | C11: 0.06 | F11: rate | G11: sourced (ADB 2017; social sector and environmental projects) | H11: ADB (2017) Guidelines for the Economic Analysis of Projects, paragraph 194 (printed page 53); DOI http://dx.doi.org/10.22617/TIM178607-2; URL https://www.adb.org/sites/default/files/institutional-document/32256/economic-analysis-projects.pdf
A12: inputs.csv | B12: discount_rate_social_nesdc | C12: 0.07 | F12: rate | G12: sourced (NESDC 2024; projects carried out from 2025 onward) | H12: NESDC (2024) Guide to Public Investment Project Appraisal, section 6.2.2 (PDF page 28); range in section 6.2.1 (PDF page 26); URL https://www.nesdc.go.th/wp-content/uploads/2025/05/article_20241009124821.pdf
A13: inputs.csv | B13: discount_rate_social_nesdc_pre2025 | C13: 0.12 | F13: rate | G13: reference only (applies to projects carried out before 2025) | H13: NESDC (2024) Guide to Public Investment Project Appraisal, section 6.2.2 (PDF page 28); URL https://www.nesdc.go.th/wp-content/uploads/2025/05/article_20241009124821.pdf
A14: inputs.csv | B14: conversion_factor_standard | C14: 0.7 | F14: ratio | G14: sourced (NESDC 2024) | H14: NESDC (2024) Guide to Public Investment Project Appraisal, summary of changes (PDF page 5); used when shadow prices cannot be computed; URL https://www.nesdc.go.th/wp-content/uploads/2025/05/article_20241009124821.pdf
A15: inputs.csv | B15: project_life_years | C15: 20 | F15: years | G15: team decision (confirmed by the leader on 14 October 2026): labelled assumption; not sourced; base 20 years | H15: assumptions.csv project_life_years (team recommendation; Revenue Department building depreciation of 5 percent a year; ADB ranges)
... A50: inputs.csv | B50: chonburi_foreign_arrivals_2019 | C50: 9966574 | F50: persons | G50: sourced (TAT Intelligence Center workbook, 2019 revised figure 2562R, foreign visitors to Chon Buri province; a provincial visitor count, not a count of border arrivals) | H50: https://intelligencecenter.tat.or.th/articles/9907 (TAT Intelligence Center domestic statistics workbook, 2019 revised figure 2562R)
A51: inputs.csv | B51: utapao_expansion_progress_overall_percent | F51: percent complete | G51: pending (the EECO page shows 0 percent, but its progress widget carries 16; the date label is October 2025; not used) | H51: https://www.eeco.or.th/en/u-tapao-airport-and-eastern-aviation-city/ (snapshot dated October 2025)
A52: inputs.csv | B52: utapao_expansion_opening_year | C52: 2031 | F52: calendar year | G52: sourced (trade news report of February 2026: operations targeted to begin in 2031; secondary, not an EEC primary; a five-year build from notice to proceed on 3 April 2026 gives the same year) | H52: https://www.britishaviationgroup.co.uk/?p=24880 (trade news report, February 2026)
A53: inputs.csv | B53: high_speed_rail_full_service_year_eeco | C53: 2031 | F53: calendar year | G53: sourced (EEC Office, page status October 2025) | H53: High-speed rail linking three airports, EEC Office. https://www.eeco.or.th/en/high-speed-rail-linking-three-airports/. Planned opening and key dates section (page status October 2025). Full high-speed rail service is expected to commence operations in 2031.
A54: inputs.csv | B54: high_speed_rail_full_service_year_wikipedia | C54: 2029 | F54: calendar year | G54: sourced (Wikipedia infobox, secondary; superseded: the article's own December 2025 status entry gives 2030, and the EEC Office page gives 2031, which is the value used) | H54: Don Mueang-Suvarnabhumi-U-Tapao high-speed railway, Wikipedia. https://en.wikipedia.org/wiki/Don_Mueang%E2%80%93Suvarnabhumi%E2%80%93U-Tapao_high-speed_railway. Infobox. Secondary source that conflicts with the 2031 date on the EEC Office page. The article gives 2030 in its status section.
A55: inputs.csv | B55: high_speed_rail_status_sep_2026 | F55: status text | G55: pending (text status: the project remains delayed; Nation Thailand article dated 7 September 2026; no numeric value) | H55: Uttapao and High-Speed Rail: EEC's Make-or-Break Infrastructure Bet, Nation Thailand (7 Sep 2026). https://www.nationthailand.com/business/economy/40070765. High-speed rail paragraph. The article states that the project remains delayed. Text value, not numeric.
A56: inputs.csv | B56: motorway7_utapao_extension_length_km | C56: 1.92 | F56: kilometres | G56: sourced (ADB news release, 6 June 2025) | H56: ADB news release, Thailand EEC infrastructure, 6 June 2025. https://www.adb.org/news/adb-supports-resilient-infrastructure-development-eastern-thailand. Project description paragraph. Department of Highways project financed by an ADB loan of USD 68.74 million, not converted.
A57: inputs.csv | B57: motorway7_utapao_extension_completion_year | C57: 2028 | F57: calendar year | G57: sourced (Thansettakij report dated 19 June 2025: expected completion July 2028, 36-month construction; secondary news source) | H57: https://www.thansettakij.com/economy/megaproject/630463 (report dated 19 June 2025; secondary news source)
A58: inputs.csv | B58: pattaya_map_ta_phut_motorway7_opening_year | C58: 2020 | F58: calendar year (opened August 2020) | G58: sourced (Pattaya Mail, 24 Aug 2020) | H58: Thai Prime Minister opens Pattaya-Map Ta Phut Highway, Pattaya Mail (24 Aug 2020). https://www.pattayamail.com/news/thai-prime-minister-opens-pattaya-map-ta-phut-highway-312223. Opening paragraph. Length and interchanges not stated in the fetched text.
A59: inputs.csv | B59: tat_spend_per_trip_all_nationalities_2023 | C59: 50900 | F59: THB per trip | G59: sourced (secondary: Government Public Relations Department report of the 2023 TAT survey, 50,900 THB per trip for all international tourists; the TAT primary document was not reached; per trip, not per park visit; not used by the model) | H59: Government Public Relations Department (relaying the 2023 TAT tourist spending survey of 30,054 tourists), https://thailand.prd.go.th/en/content/category/detail/id/52/iid/266973
A60: inputs.csv | B60: tat_spend_per_trip_middle_eastern_2023 | C60: 88512 | F60: THB per person per trip | G60: unconfirmed (88,512 THB per person per trip for the Middle Eastern market group in 2023, via secondary coverage; not used in the model) | H60: Pending. Pattaya Mail (10 May 2025, https://www.pattayamail.com/latestnews/news/middle-eastern-tourists-top-spending-charts-in-thailand-with-uae-visitors-averaging-over-thb-8800-daily-500402) attributes the figure to TAT 2023 data. The TAT primary document was not fetched.
A61: inputs.csv | B61: tat_spend_per_day_uae_2023 | C61: 8834 | F61: THB per person per day | G61: unconfirmed (8,834 THB per person per day for UAE visitors in 2023, via secondary coverage; not used in the model) | H61: Pending. The same Pattaya Mail article (10 May 2025) attributes the figure to TAT 2023 data. The TAT primary document was not fetched.
A62: inputs.csv | B62: tat_spend_per_night_by_nationality_2024_2025 | F62: THB per person per night | G62: pending (not found in any source read) | H62: No source found. The TAT survey article gives no per-night figures.
A63: inputs.csv | B63: tat_spend_per_trip_by_nationality_2024_2025_official | F63: THB per person per trip | G63: pending (TAT news releases give 2025 partial-year values: China 54,230 THB per trip to 12 December 2025; Singapore 45,000 to September 2025; Japan about 39,000 THB per person to 18 September 2025; three nationalities and periods, so no single value is entered) | H63: https://www.tatnews.org/?p=84576 (TAT news releases; further pages ?p=83305 and ?p=82974)
A64: inputs.csv | B64: mots_spend_per_trip_all_tourists_2019 | C64: 48580 | F64: THB per international tourist per trip | G64: sourced (Ministry of Tourism and Sports, spending per trip of foreign tourists, 2019, preliminary) | H64: https://www.mots.go.th/download/article/article_20200123132729.pdf (Ministry of Tourism and Sports, 2019, preliminary)
A65: inputs.csv | B65: mots_spend_per_day_all_tourists_2019 | C65: 5172.29 | F65: THB per international tourist per day | G65: sourced (Ministry of Tourism and Sports, spending per day of foreign tourists, 2019 full-year summary) | H65: https://www.mots.go.th/download/article/article_20201104090605.pdf (Ministry of Tourism and Sports, 2019 full-year summary)
A66: inputs.csv | B66: intl_avg_length_of_stay_2016_days | C66: 9.6 | F66: days | G66: sourced (NSO Indicators Economic 2562, Table 8.1, average length of stay of international tourists 2016) | H66: https://www.nso.go.th/public/e-book/Indicators-Economic/Indicators-Economic-2562/files/assets/basic-html/page134.html, Table 8.1 (printed page 107), international block, 2016
A67: inputs.csv | B67: intl_avg_length_of_stay_2024_days | C67: 9.4 | F67: days | G67: sourced (MoTS statistics workbook, average length of stay 2024, all international arrivals) | H67: https://www.mots.go.th/images/v2022_c1331820-8936-4423-84cd-65278cebf658.xlsx, sheet Q1-Q4, row Grand Total, column Length of Stay (Days) (2024)
A68: inputs.csv | B68: intl_first_visit_share_2024 | F68: percent of international arrivals on first visit | G68: pending (not found in any source read) | H68: Not found on a fetched TAT page. Niche segment and platform figures are not national and are not used.
A69: inputs.csv | B69: thai_domestic_spend_per_trip_2024 | C69: 4000 | F69: THB per person per domestic trip | G69: unconfirmed (about 4,000 THB per domestic trip, stated as current in an article dated 1 September 2024; no period and no primary source) | H69: No fetched source. A search summary citing TAT domestic data was not verified.
A70: inputs.csv | B70: thai_resident_attraction_visit_share_2024 | F70: percent of attraction visits by Thai residents | G70: pending (not found in any source read) | H70: Not found.
A71: inputs.csv | B71: intl_arrivals_2025 | C71: 32974321 | F71: persons | G71: sourced (MoTS statistics workbook, international arrivals 2025, January to December) | H71: https://www.mots.go.th/images/v2022_5a7fbad7-1fcf-4410-a387-f29bb17486e2.xlsx, sheet Q1-Q4, row Grand Total, column No. of Arrivals (2025)
A72: inputs.csv | B72: intl_arrivals_2024 | C72: 35545714 | F72: persons | G72: sourced (provisional: Ministry of Tourism and Sports workbook, 2024p, January to December; file footer as at 1 January 2026) | H72: https://www.mots.go.th/images/v2022_875a5789-3bcc-4700-bf55-b86fa7f1053c.xlsx (Ministry of Tourism and Sports workbook, Grand Total, 2024p, January to December)
A73: inputs.csv | B73: intl_arrivals_2019 | C73: 39916251 | F73: persons | G73: sourced (Ministry of Tourism and Sports workbook, 2019 year total, revised figure 2562R) | H73: https://www.mots.go.th/download/article/article_20201103140333.xlsx (Ministry of Tourism and Sports workbook, 2019 year total, revised 2562R, updated October 2020)
A74: inputs.csv | B74: intl_arrivals_2020 | C74: 6725000 | F74: persons | G74: sourced (NSO Thai Economic Indicators 2025, Table 8.1, international tourist arrivals 2020) | H74: https://www.nso.go.th/public/e-book/Indicators-Economic/Thai_Economic_Indicators_2025/158, Table 8.1, 2020
...

Sheet Appraisal
A1: Operator financial appraisal: legacy-model reconciliation and cash-cost proxy (base case, THB billion unless stated)
A2: Legacy-model reconciliation using the original cost scope, with a separate cash-cost proxy. Results remain provisional. Years t = 0 to 22 from the start of construction. Cells are formulas linked to Inputs.
A3: Limits: not a complete Financial Appraisal. The cash basis is a proxy from Hong Kong Disneyland FY2025 accounts. Not modelled: cash tax, replacement capex, working capital, and the park-only capex and revenue boundary. The depreciation treatment is pending the team decision.
A4: Parameter | B4: Confirmed basis | C4: Cash basis
A5: Operating-cost share of revenue | B5: =Inputs!$C$153 | C5: =Inputs!$C$135/Inputs!$C$86
A6: WACC (financial cost of capital) | B6: =Inputs!$C$145 | C6: =B6
A7: Project life (years of operation) | B7: =Inputs!$C$143
A8: Construction years | B8: =Inputs!$C$144
A9: Capital expenditure (THB bn, proposal value, not verified) | B9: =Inputs!$C$4
A10: Attendance (million visits a year) | B10: =Inputs!$C$146
A11: International share of attendance | B11: =Inputs!$C$147
A12: Physical visit cap (million visits a year): smaller of airport and room-stock capacity | B12: =MIN(Inputs!$C$28/Inputs!$C$157,Inputs!$C$161*365*Inputs!$C$156/Inputs!$C$155)/1000000
A13: Ticket revenue per visit (THB) | B13: =Inputs!$C$154
A14: Operator visits per operating year (million): attendance less international visits above the cap | B14: =B10-MAX(B10*B11-B12,0)
A15: Operator revenue per operating year (THB bn) | B15: =B14*B13/1000
A17: Results | B17: Confirmed basis | C17: Cash basis
A18: Operator NPV at the financial cost of capital (THB bn) | B18: =SUM(J31:J53) | C18: =SUM(N31:N53)
A19: Operator IRR | B19: =IRR(I31:I53) | C19: =IRR(M31:M53)
A20: Break-even capital expenditure (THB bn), NPV = 0 | B20: =B9*(B15*(1-B5)*B26)/B27 | C20: =B9*(B15*(1-C5)*B26)/B27
A21: Break-even attendance (million visits a year), NPV = 0 | B21: =B10-B18/((1-B5)*B13/1000*(1-B11)*B26) | C21: =B10-C18/((1-C5)*B13/1000*(1-B11)*B26)
A22: Regime check for break-even attendance (OK when the break-even attendance is above the cap) | B22: =IF(B21*B11>=B12,"OK","CHECK") | C22: =IF(C21*B11>=B12,"OK","CHECK")
A23: Model reference NPV (scratch run of the model, 20 Oct 2026; for audit only) | B23: -280.94127 | C23: -259.41978
A24: Difference from the model reference (should be about 0) | B24: =B18-B23 | C24: =C18-C23
A26: Sum of discount factors over operating years (AF0) | B26: =SUMPRODUCT(B31:B53,D31:D53)
A27: Present value of capital expenditure at the proposal value (PVcap, THB bn) | B27: =SUMPRODUCT(E31:E53,B31:B53)
A30: Year t | B30: Discount factor | C30: Construction flag | D30: Operating flag | E30: Capex (THB bn) | F30: Operator visits (million) | G30: Revenue (THB bn) | H30: Opex, confirmed (THB bn) | I30: Cash flow, confirmed | J30: PV, confirmed | K30: Cumulative, confirmed | L30: Opex, cash basis (THB bn) | M30: Cash flow, cash basis | N30: PV, cash basis | O30: Cumulative, cash basis
A31: 0 | B31: =1/(1+$B$6)^A31 | C31: =IF(A31<$B$8,1,0) | D31: =IF(AND(A31>=$B$8,A31<$B$8+$B$7),1,0) | E31: =C31*$B$9/$B$8 | F31: =D31*$B$14 | G31: =F31*$B$13/1000 | H31: =$B$5*G31 | I31: =G31-H31-E31 | J31: =I31*B31 | K31: =SUM($I$31:I31) | L31: =$C$5*G31 | M31: =G31-L31-E31 | N31: =M31*B31 | O31: =SUM($M$31:M31)
A32: 1 | B32: =1/(1+$B$6)^A32 | C32: =IF(A32<$B$8,1,0) | D32: =IF(AND(A32>=$B$8,A32<$B$8+$B$7),1,0) | E32: =C32*$B$9/$B$8 | F32: =D32*$B$14 | G32: =F32*$B$13/1000 | H32: =$B$5*G32 | I32: =G32-H32-E32 | J32: =I32*B32 | K32: =SUM($I$31:I32) | L32: =$C$5*G32 | M32: =G32-L32-E32 | N32: =M32*B32 | O32: =SUM($M$31:M32)
A33: 2 | B33: =1/(1+$B$6)^A33 | C33: =IF(A33<$B$8,1,0) | D33: =IF(AND(A33>=$B$8,A33<$B$8+$B$7),1,0) | E33: =C33*$B$9/$B$8 | F33: =D33*$B$14 | G33: =F33*$B$13/1000 | H33: =$B$5*G33 | I33: =G33-H33-E33 | J33: =I33*B33 | K33: =SUM($I$31:I33) | L33: =$C$5*G33 | M33: =G33-L33-E33 | N33: =M33*B33 | O33: =SUM($M$31:M33)
A34: 3 | B34: =1/(1+$B$6)^A34 | C34: =IF(A34<$B$8,1,0) | D34: =IF(AND(A34>=$B$8,A34<$B$8+$B$7),1,0) | E34: =C34*$B$9/$B$8 | F34: =D34*$B$14 | G34: =F34*$B$13/1000 | H34: =$B$5*G34 | I34: =G34-H34-E34 | J34: =I34*B34 | K34: =SUM($I$31:I34) | L34: =$C$5*G34 | M34: =G34-L34-E34 | N34: =M34*B34 | O34: =SUM($M$31:M34)
A35: 4 | B35: =1/(1+$B$6)^A35 | C35: =IF(A35<$B$8,1,0) | D35: =IF(AND(A35>=$B$8,A35<$B$8+$B$7),1,0) | E35: =C35*$B$9/$B$8 | F35: =D35*$B$14 | G35: =F35*$B$13/1000 | H35: =$B$5*G35 | I35: =G35-H35-E35 | J35: =I35*B35 | K35: =SUM($I$31:I35) | L35: =$C$5*G35 | M35: =G35-L35-E35 | N35: =M35*B35 | O35: =SUM($M$31:M35)
A36: 5 | B36: =1/(1+$B$6)^A36 | C36: =IF(A36<$B$8,1,0) | D36: =IF(AND(A36>=$B$8,A36<$B$8+$B$7),1,0) | E36: =C36*$B$9/$B$8 | F36: =D36*$B$14 | G36: =F36*$B$13/1000 | H36: =$B$5*G36 | I36: =G36-H36-E36 | J36: =I36*B36 | K36: =SUM($I$31:I36) | L36: =$C$5*G36 | M36: =G36-L36-E36 | N36: =M36*B36 | O36: =SUM($M$31:M36)
A37: 6 | B37: =1/(1+$B$6)^A37 | C37: =IF(A37<$B$8,1,0) | D37: =IF(AND(A37>=$B$8,A37<$B$8+$B$7),1,0) | E37: =C37*$B$9/$B$8 | F37: =D37*$B$14 | G37: =F37*$B$13/1000 | H37: =$B$5*G37 | I37: =G37-H37-E37 | J37: =I37*B37 | K37: =SUM($I$31:I37) | L37: =$C$5*G37 | M37: =G37-L37-E37 | N37: =M37*B37 | O37: =SUM($M$31:M37)
A38: 7 | B38: =1/(1+$B$6)^A38 | C38: =IF(A38<$B$8,1,0) | D38: =IF(AND(A38>=$B$8,A38<$B$8+$B$7),1,0) | E38: =C38*$B$9/$B$8 | F38: =D38*$B$14 | G38: =F38*$B$13/1000 | H38: =$B$5*G38 | I38: =G38-H38-E38 | J38: =I38*B38 | K38: =SUM($I$31:I38) | L38: =$C$5*G38 | M38: =G38-L38-E38 | N38: =M38*B38 | O38: =SUM($M$31:M38)
A39: 8 | B39: =1/(1+$B$6)^A39 | C39: =IF(A39<$B$8,1,0) | D39: =IF(AND(A39>=$B$8,A39<$B$8+$B$7),1,0) | E39: =C39*$B$9/$B$8 | F39: =D39*$B$14 | G39: =F39*$B$13/1000 | H39: =$B$5*G39 | I39: =G39-H39-E39 | J39: =I39*B39 | K39: =SUM($I$31:I39) | L39: =$C$5*G39 | M39: =G39-L39-E39 | N39: =M39*B39 | O39: =SUM($M$31:M39)
A40: 9 | B40: =1/(1+$B$6)^A40 | C40: =IF(A40<$B$8,1,0) | D40: =IF(AND(A40>=$B$8,A40<$B$8+$B$7),1,0) | E40: =C40*$B$9/$B$8 | F40: =D40*$B$14 | G40: =F40*$B$13/1000 | H40: =$B$5*G40 | I40: =G40-H40-E40 | J40: =I40*B40 | K40: =SUM($I$31:I40) | L40: =$C$5*G40 | M40: =G40-L40-E40 | N40: =M40*B40 | O40: =SUM($M$31:M40)
A41: 10 | B41: =1/(1+$B$6)^A41 | C41: =IF(A41<$B$8,1,0) | D41: =IF(AND(A41>=$B$8,A41<$B$8+$B$7),1,0) | E41: =C41*$B$9/$B$8 | F41: =D41*$B$14 | G41: =F41*$B$13/1000 | H41: =$B$5*G41 | I41: =G41-H41-E41 | J41: =I41*B41 | K41: =SUM($I$31:I41) | L41: =$C$5*G41 | M41: =G41-L41-E41 | N41: =M41*B41 | O41: =SUM($M$31:M41)
A42: 11 | B42: =1/(1+$B$6)^A42 | C42: =IF(A42<$B$8,1,0) | D42: =IF(AND(A42>=$B$8,A42<$B$8+$B$7),1,0) | E42: =C42*$B$9/$B$8 | F42: =D42*$B$14 | G42: =F42*$B$13/1000 | H42: =$B$5*G42 | I42: =G42-H42-E42 | J42: =I42*B42 | K42: =SUM($I$31:I42) | L42: =$C$5*G42 | M42: =G42-L42-E42 | N42: =M42*B42 | O42: =SUM($M$31:M42)
... A53: 22 | B53: =1/(1+$B$6)^A53 | C53: =IF(A53<$B$8,1,0) | D53: =IF(AND(A53>=$B$8,A53<$B$8+$B$7),1,0) | E53: =C53*$B$9/$B$8 | F53: =D53*$B$14 | G53: =F53*$B$13/1000 | H53: =$B$5*G53 | I53: =G53-H53-E53 | J53: =I53*B53 | K53: =SUM($I$31:I53) | L53: =$C$5*G53 | M53: =G53-L53-E53 | N53: =M53*B53 | O53: =SUM($M$31:M53)
A55: Sensitivity cases (formula-based). The model reference column is the scratch run of the model on the confirmed basis.
...

Sheet Charts
A1: Charts built from the Appraisal sheet (native Excel charts linked to the cells, so they update with the inputs)
